[2023-07-27T06:45:19.231+0000] {taskinstance.py:1087} INFO - Dependencies all met for <TaskInstance: data_engineer_jobs_dag.extract_relevant_records_from_overall_data scheduled__2022-01-08T00:00:00+00:00 [queued]>
[2023-07-27T06:45:19.406+0000] {taskinstance.py:1087} INFO - Dependencies all met for <TaskInstance: data_engineer_jobs_dag.extract_relevant_records_from_overall_data scheduled__2022-01-08T00:00:00+00:00 [queued]>
[2023-07-27T06:45:19.407+0000] {taskinstance.py:1283} INFO - 
--------------------------------------------------------------------------------
[2023-07-27T06:45:19.457+0000] {taskinstance.py:1284} INFO - Starting attempt 2 of 2
[2023-07-27T06:45:19.462+0000] {taskinstance.py:1285} INFO - 
--------------------------------------------------------------------------------
[2023-07-27T06:45:20.150+0000] {taskinstance.py:1081} INFO - Dependencies not met for <TaskInstance: data_engineer_jobs_dag.extract_relevant_records_from_overall_data scheduled__2022-01-08T00:00:00+00:00 [running]>, dependency 'Task Instance State' FAILED: Task is in the 'running' state.
[2023-07-27T06:45:20.153+0000] {taskinstance.py:1081} INFO - Dependencies not met for <TaskInstance: data_engineer_jobs_dag.extract_relevant_records_from_overall_data scheduled__2022-01-08T00:00:00+00:00 [running]>, dependency 'Task Instance Not Running' FAILED: Task is in the running state
[2023-07-27T06:45:20.183+0000] {taskinstance.py:1304} INFO - Executing <Task(PythonOperator): extract_relevant_records_from_overall_data> on 2022-01-08 00:00:00+00:00
[2023-07-27T06:45:20.207+0000] {standard_task_runner.py:55} INFO - Started process 117 to run task
[2023-07-27T06:45:20.294+0000] {standard_task_runner.py:82} INFO - Running: ['***', 'tasks', 'run', 'data_engineer_jobs_dag', 'extract_relevant_records_from_overall_data', 'scheduled__2022-01-08T00:00:00+00:00', '--job-id', '78', '--raw', '--subdir', 'DAGS_FOLDER/load_data.py', '--cfg-path', '/tmp/tmp5k9tb0kq']
[2023-07-27T06:45:20.372+0000] {standard_task_runner.py:83} INFO - Job 78: Subtask extract_relevant_records_from_overall_data
[2023-07-27T06:45:20.684+0000] {local_task_job.py:98} INFO - Task is not able to be run
[2023-07-27T06:45:22.096+0000] {task_command.py:389} INFO - Running <TaskInstance: data_engineer_jobs_dag.extract_relevant_records_from_overall_data scheduled__2022-01-08T00:00:00+00:00 [running]> on host bc3380e7707e
[2023-07-27T06:45:25.006+0000] {taskinstance.py:1513} INFO - Exporting the following env vars:
AIRFLOW_CTX_DAG_EMAIL=your-email@example.com
AIRFLOW_CTX_DAG_OWNER=ebejale
AIRFLOW_CTX_DAG_ID=data_engineer_jobs_dag
AIRFLOW_CTX_TASK_ID=extract_relevant_records_from_overall_data
AIRFLOW_CTX_EXECUTION_DATE=2022-01-08T00:00:00+00:00
AIRFLOW_CTX_TRY_NUMBER=2
AIRFLOW_CTX_DAG_RUN_ID=scheduled__2022-01-08T00:00:00+00:00
[2023-07-27T06:45:25.172+0000] {taskinstance.py:1772} ERROR - Task failed with exception
Traceback (most recent call last):
  File "/home/airflow/.local/lib/python3.7/site-packages/airflow/operators/python.py", line 175, in execute
    return_value = self.execute_callable()
  File "/home/airflow/.local/lib/python3.7/site-packages/airflow/operators/python.py", line 192, in execute_callable
    return self.python_callable(*self.op_args, **self.op_kwargs)
  File "/opt/airflow/dags/load_data.py", line 63, in extract_relevant_records_from_overall_data
    for i in range(len(data['data'])):
KeyError: 'data'
[2023-07-27T06:45:25.307+0000] {taskinstance.py:1327} INFO - Marking task as FAILED. dag_id=data_engineer_jobs_dag, task_id=extract_relevant_records_from_overall_data, execution_date=20220108T000000, start_date=20230727T064519, end_date=20230727T064525
[2023-07-27T06:45:26.068+0000] {standard_task_runner.py:105} ERROR - Failed to execute job 78 for task extract_relevant_records_from_overall_data ('data'; 117)
[2023-07-27T06:45:26.166+0000] {local_task_job.py:159} INFO - Task exited with return code 1
[2023-07-27T06:45:26.521+0000] {taskinstance.py:2582} INFO - 0 downstream tasks scheduled from follow-on schedule check
