[2023-07-29T13:01:34.520+0000] {taskinstance.py:1087} INFO - Dependencies all met for <TaskInstance: my_postgres_dag_v3-1.insert_data manual__2023-07-29T13:00:20.871224+00:00 [queued]>
[2023-07-29T13:01:34.868+0000] {taskinstance.py:1087} INFO - Dependencies all met for <TaskInstance: my_postgres_dag_v3-1.insert_data manual__2023-07-29T13:00:20.871224+00:00 [queued]>
[2023-07-29T13:01:34.875+0000] {taskinstance.py:1283} INFO - 
--------------------------------------------------------------------------------
[2023-07-29T13:01:34.900+0000] {taskinstance.py:1284} INFO - Starting attempt 1 of 3
[2023-07-29T13:01:34.901+0000] {taskinstance.py:1285} INFO - 
--------------------------------------------------------------------------------
[2023-07-29T13:01:35.196+0000] {taskinstance.py:1304} INFO - Executing <Task(PostgresOperator): insert_data> on 2023-07-29 13:00:20.871224+00:00
[2023-07-29T13:01:35.380+0000] {standard_task_runner.py:55} INFO - Started process 6250 to run task
[2023-07-29T13:01:35.537+0000] {standard_task_runner.py:82} INFO - Running: ['***', 'tasks', 'run', 'my_postgres_dag_v3-1', 'insert_data', 'manual__2023-07-29T13:00:20.871224+00:00', '--job-id', '2069', '--raw', '--subdir', 'DAGS_FOLDER/postgres_operator_v2-2.py', '--cfg-path', '/tmp/tmp9g15drk3']
[2023-07-29T13:01:35.657+0000] {standard_task_runner.py:83} INFO - Job 2069: Subtask insert_data
[2023-07-29T13:01:37.744+0000] {task_command.py:389} INFO - Running <TaskInstance: my_postgres_dag_v3-1.insert_data manual__2023-07-29T13:00:20.871224+00:00 [running]> on host f1ea17bde741
[2023-07-29T13:01:41.377+0000] {taskinstance.py:1513} INFO - Exporting the following env vars:
AIRFLOW_CTX_DAG_OWNER=Byron
AIRFLOW_CTX_DAG_ID=my_postgres_dag_v3-1
AIRFLOW_CTX_TASK_ID=insert_data
AIRFLOW_CTX_EXECUTION_DATE=2023-07-29T13:00:20.871224+00:00
AIRFLOW_CTX_TRY_NUMBER=1
AIRFLOW_CTX_DAG_RUN_ID=manual__2023-07-29T13:00:20.871224+00:00
[2023-07-29T13:01:41.397+0000] {sql.py:253} INFO - Executing: INSERT INTO ***_users (name) VALUES ("Chidi", "Joseph", "Cindy", "Sarai")
[2023-07-29T13:01:41.833+0000] {base.py:73} INFO - Using connection ID 'my_connection' for task execution.
[2023-07-29T13:01:52.650+0000] {base.py:73} INFO - Using connection ID 'my_connection' for task execution.
[2023-07-29T13:01:54.126+0000] {sql.py:364} INFO - Running statement: INSERT INTO ***_users (name) VALUES ("Chidi", "Joseph", "Cindy", "Sarai"), parameters: None
[2023-07-29T13:01:54.660+0000] {taskinstance.py:1772} ERROR - Task failed with exception
Traceback (most recent call last):
  File "/home/airflow/.local/lib/python3.7/site-packages/airflow/providers/common/sql/operators/sql.py", line 261, in execute
    return_last=self.return_last,
  File "/home/airflow/.local/lib/python3.7/site-packages/airflow/providers/common/sql/hooks/sql.py", line 338, in run
    self._run_command(cur, sql_statement, parameters)
  File "/home/airflow/.local/lib/python3.7/site-packages/airflow/providers/common/sql/hooks/sql.py", line 369, in _run_command
    cur.execute(sql_statement)
psycopg2.errors.UndefinedColumn: column "Chidi" does not exist
LINE 1: INSERT INTO ***_users (name) VALUES ("Chidi", "Joseph", ...
                                                 ^

[2023-07-29T13:01:55.180+0000] {taskinstance.py:1327} INFO - Marking task as UP_FOR_RETRY. dag_id=my_postgres_dag_v3-1, task_id=insert_data, execution_date=20230729T130020, start_date=20230729T130134, end_date=20230729T130155
[2023-07-29T13:01:56.253+0000] {standard_task_runner.py:105} ERROR - Failed to execute job 2069 for task insert_data (column "Chidi" does not exist
LINE 1: INSERT INTO ***_users (name) VALUES ("Chidi", "Joseph", ...
                                                 ^
; 6250)
[2023-07-29T13:01:56.748+0000] {local_task_job.py:159} INFO - Task exited with return code 1
[2023-07-29T13:01:57.550+0000] {taskinstance.py:2582} INFO - 0 downstream tasks scheduled from follow-on schedule check
