[2023-07-29T12:24:50.591+0000] {taskinstance.py:1087} INFO - Dependencies all met for <TaskInstance: my_postgres_dag_v1.create_table scheduled__2023-07-27T00:00:00+00:00 [queued]>
[2023-07-29T12:24:50.685+0000] {taskinstance.py:1087} INFO - Dependencies all met for <TaskInstance: my_postgres_dag_v1.create_table scheduled__2023-07-27T00:00:00+00:00 [queued]>
[2023-07-29T12:24:50.695+0000] {taskinstance.py:1283} INFO - 
--------------------------------------------------------------------------------
[2023-07-29T12:24:50.708+0000] {taskinstance.py:1284} INFO - Starting attempt 1 of 3
[2023-07-29T12:24:50.711+0000] {taskinstance.py:1285} INFO - 
--------------------------------------------------------------------------------
[2023-07-29T12:24:51.097+0000] {taskinstance.py:1304} INFO - Executing <Task(PostgresOperator): create_table> on 2023-07-27 00:00:00+00:00
[2023-07-29T12:24:51.116+0000] {standard_task_runner.py:55} INFO - Started process 4956 to run task
[2023-07-29T12:24:51.153+0000] {standard_task_runner.py:82} INFO - Running: ['***', 'tasks', 'run', 'my_postgres_dag_v1', 'create_table', 'scheduled__2023-07-27T00:00:00+00:00', '--job-id', '2028', '--raw', '--subdir', 'DAGS_FOLDER/postgres_operator_v1-1.py', '--cfg-path', '/tmp/tmpp6mpx7o2']
[2023-07-29T12:24:51.166+0000] {standard_task_runner.py:83} INFO - Job 2028: Subtask create_table
[2023-07-29T12:24:53.263+0000] {task_command.py:389} INFO - Running <TaskInstance: my_postgres_dag_v1.create_table scheduled__2023-07-27T00:00:00+00:00 [running]> on host f1ea17bde741
[2023-07-29T12:24:56.449+0000] {taskinstance.py:1513} INFO - Exporting the following env vars:
AIRFLOW_CTX_DAG_OWNER=Byron
AIRFLOW_CTX_DAG_ID=my_postgres_dag_v1
AIRFLOW_CTX_TASK_ID=create_table
AIRFLOW_CTX_EXECUTION_DATE=2023-07-27T00:00:00+00:00
AIRFLOW_CTX_TRY_NUMBER=1
AIRFLOW_CTX_DAG_RUN_ID=scheduled__2023-07-27T00:00:00+00:00
[2023-07-29T12:24:56.796+0000] {sql.py:253} INFO - Executing: CREATE TABLE IF NOT EXISTS ***_users (id SERIAL PRIMARY KEY, name VARCHAR(30))
[2023-07-29T12:24:57.610+0000] {base.py:73} INFO - Using connection ID 'my_connection' for task execution.
[2023-07-29T12:25:08.618+0000] {base.py:73} INFO - Using connection ID 'my_connection' for task execution.
[2023-07-29T12:25:09.774+0000] {taskinstance.py:1772} ERROR - Task failed with exception
Traceback (most recent call last):
  File "/home/airflow/.local/lib/python3.7/site-packages/airflow/providers/common/sql/operators/sql.py", line 261, in execute
    return_last=self.return_last,
  File "/home/airflow/.local/lib/python3.7/site-packages/airflow/providers/common/sql/hooks/sql.py", line 331, in run
    with closing(self.get_conn()) as conn:
  File "/home/airflow/.local/lib/python3.7/site-packages/airflow/providers/postgres/hooks/postgres.py", line 144, in get_conn
    self.conn = psycopg2.connect(**conn_args)
  File "/home/airflow/.local/lib/python3.7/site-packages/psycopg2/__init__.py", line 122, in connect
    conn = _connect(dsn, connection_factory=connection_factory, **kwasync)
psycopg2.OperationalError: connection to server at "host.docker.internal" (192.168.65.254), port 5432 failed: FATAL:  database "test_db" does not exist

[2023-07-29T12:25:10.009+0000] {taskinstance.py:1327} INFO - Marking task as UP_FOR_RETRY. dag_id=my_postgres_dag_v1, task_id=create_table, execution_date=20230727T000000, start_date=20230729T122450, end_date=20230729T122510
[2023-07-29T12:25:12.129+0000] {standard_task_runner.py:105} ERROR - Failed to execute job 2028 for task create_table (connection to server at "host.docker.internal" (192.168.65.254), port 5432 failed: FATAL:  database "test_db" does not exist
; 4956)
[2023-07-29T12:25:12.922+0000] {local_task_job.py:159} INFO - Task exited with return code 1
[2023-07-29T12:25:13.462+0000] {taskinstance.py:2582} INFO - 0 downstream tasks scheduled from follow-on schedule check
