[2023-07-31T12:46:40.571+0000] {taskinstance.py:1087} INFO - Dependencies all met for <TaskInstance: job_data_pipeline_plus_csv.get_jobs manual__2023-07-31T12:46:11.714766+00:00 [queued]>
[2023-07-31T12:46:40.746+0000] {taskinstance.py:1087} INFO - Dependencies all met for <TaskInstance: job_data_pipeline_plus_csv.get_jobs manual__2023-07-31T12:46:11.714766+00:00 [queued]>
[2023-07-31T12:46:40.761+0000] {taskinstance.py:1283} INFO - 
--------------------------------------------------------------------------------
[2023-07-31T12:46:40.809+0000] {taskinstance.py:1284} INFO - Starting attempt 1 of 2
[2023-07-31T12:46:40.825+0000] {taskinstance.py:1285} INFO - 
--------------------------------------------------------------------------------
[2023-07-31T12:46:41.771+0000] {taskinstance.py:1304} INFO - Executing <Task(PythonOperator): get_jobs> on 2023-07-31 12:46:11.714766+00:00
[2023-07-31T12:46:41.869+0000] {standard_task_runner.py:55} INFO - Started process 3138 to run task
[2023-07-31T12:46:41.932+0000] {standard_task_runner.py:82} INFO - Running: ['***', 'tasks', 'run', 'job_data_pipeline_plus_csv', 'get_jobs', 'manual__2023-07-31T12:46:11.714766+00:00', '--job-id', '3126', '--raw', '--subdir', 'DAGS_FOLDER/load_data_create_csv(Y).py', '--cfg-path', '/tmp/tmpttpf_f6q']
[2023-07-31T12:46:41.965+0000] {standard_task_runner.py:83} INFO - Job 3126: Subtask get_jobs
[2023-07-31T12:46:43.601+0000] {task_command.py:389} INFO - Running <TaskInstance: job_data_pipeline_plus_csv.get_jobs manual__2023-07-31T12:46:11.714766+00:00 [running]> on host 4b7777060932
[2023-07-31T12:46:45.171+0000] {taskinstance.py:1513} INFO - Exporting the following env vars:
AIRFLOW_CTX_DAG_OWNER=***
AIRFLOW_CTX_DAG_ID=job_data_pipeline_plus_csv
AIRFLOW_CTX_TASK_ID=get_jobs
AIRFLOW_CTX_EXECUTION_DATE=2023-07-31T12:46:11.714766+00:00
AIRFLOW_CTX_TRY_NUMBER=1
AIRFLOW_CTX_DAG_RUN_ID=manual__2023-07-31T12:46:11.714766+00:00
[2023-07-31T12:46:53.303+0000] {taskinstance.py:1772} ERROR - Task failed with exception
Traceback (most recent call last):
  File "/home/airflow/.local/lib/python3.7/site-packages/urllib3/connection.py", line 175, in _new_conn
    (self._dns_host, self.port), self.timeout, **extra_kw
  File "/home/airflow/.local/lib/python3.7/site-packages/urllib3/util/connection.py", line 72, in create_connection
    for res in socket.getaddrinfo(host, port, family, socket.SOCK_STREAM):
  File "/usr/local/lib/python3.7/socket.py", line 752, in getaddrinfo
    for res in _socket.getaddrinfo(host, port, family, type, proto, flags):
socket.gaierror: [Errno -3] Temporary failure in name resolution

During handling of the above exception, another exception occurred:

Traceback (most recent call last):
  File "/home/airflow/.local/lib/python3.7/site-packages/urllib3/connectionpool.py", line 710, in urlopen
    chunked=chunked,
  File "/home/airflow/.local/lib/python3.7/site-packages/urllib3/connectionpool.py", line 386, in _make_request
    self._validate_conn(conn)
  File "/home/airflow/.local/lib/python3.7/site-packages/urllib3/connectionpool.py", line 1042, in _validate_conn
    conn.connect()
  File "/home/airflow/.local/lib/python3.7/site-packages/urllib3/connection.py", line 358, in connect
    self.sock = conn = self._new_conn()
  File "/home/airflow/.local/lib/python3.7/site-packages/urllib3/connection.py", line 187, in _new_conn
    self, "Failed to establish a new connection: %s" % e
urllib3.exceptions.NewConnectionError: <urllib3.connection.HTTPSConnection object at 0x7f8d3f86a0d0>: Failed to establish a new connection: [Errno -3] Temporary failure in name resolution

During handling of the above exception, another exception occurred:

Traceback (most recent call last):
  File "/home/airflow/.local/lib/python3.7/site-packages/requests/adapters.py", line 499, in send
    timeout=timeout,
  File "/home/airflow/.local/lib/python3.7/site-packages/urllib3/connectionpool.py", line 788, in urlopen
    method, url, error=e, _pool=self, _stacktrace=sys.exc_info()[2]
  File "/home/airflow/.local/lib/python3.7/site-packages/urllib3/util/retry.py", line 592, in increment
    raise MaxRetryError(_pool, url, error or ResponseError(cause))
urllib3.exceptions.MaxRetryError: HTTPSConnectionPool(host='api.adzuna.com', port=443): Max retries exceeded with url: /v1/api/jobs/gb/search/1?where=London&what=data+engineer&app_id=a432e053&app_key=58ee1ddf863f2d700a6eea8c9d8ccb12 (Caused by NewConnectionError('<urllib3.connection.HTTPSConnection object at 0x7f8d3f86a0d0>: Failed to establish a new connection: [Errno -3] Temporary failure in name resolution'))

During handling of the above exception, another exception occurred:

Traceback (most recent call last):
  File "/home/airflow/.local/lib/python3.7/site-packages/airflow/operators/python.py", line 175, in execute
    return_value = self.execute_callable()
  File "/home/airflow/.local/lib/python3.7/site-packages/airflow/operators/python.py", line 192, in execute_callable
    return self.python_callable(*self.op_args, **self.op_kwargs)
  File "/opt/airflow/dags/load_data_create_csv(Y).py", line 29, in get_jobs
    response = requests.get(url, params=params)
  File "/home/airflow/.local/lib/python3.7/site-packages/requests/api.py", line 73, in get
    return request("get", url, params=params, **kwargs)
  File "/home/airflow/.local/lib/python3.7/site-packages/requests/api.py", line 59, in request
    return session.request(method=method, url=url, **kwargs)
  File "/home/airflow/.local/lib/python3.7/site-packages/requests/sessions.py", line 587, in request
    resp = self.send(prep, **send_kwargs)
  File "/home/airflow/.local/lib/python3.7/site-packages/requests/sessions.py", line 701, in send
    r = adapter.send(request, **kwargs)
  File "/home/airflow/.local/lib/python3.7/site-packages/requests/adapters.py", line 565, in send
    raise ConnectionError(e, request=request)
requests.exceptions.ConnectionError: HTTPSConnectionPool(host='api.adzuna.com', port=443): Max retries exceeded with url: /v1/api/jobs/gb/search/1?where=London&what=data+engineer&app_id=a432e053&app_key=58ee1ddf863f2d700a6eea8c9d8ccb12 (Caused by NewConnectionError('<urllib3.connection.HTTPSConnection object at 0x7f8d3f86a0d0>: Failed to establish a new connection: [Errno -3] Temporary failure in name resolution'))
[2023-07-31T12:46:53.928+0000] {taskinstance.py:1327} INFO - Marking task as UP_FOR_RETRY. dag_id=job_data_pipeline_plus_csv, task_id=get_jobs, execution_date=20230731T124611, start_date=20230731T124640, end_date=20230731T124653
[2023-07-31T12:46:54.341+0000] {standard_task_runner.py:105} ERROR - Failed to execute job 3126 for task get_jobs (HTTPSConnectionPool(host='api.adzuna.com', port=443): Max retries exceeded with url: /v1/api/jobs/gb/search/1?where=London&what=data+engineer&app_id=a432e053&app_key=58ee1ddf863f2d700a6eea8c9d8ccb12 (Caused by NewConnectionError('<urllib3.connection.HTTPSConnection object at 0x7f8d3f86a0d0>: Failed to establish a new connection: [Errno -3] Temporary failure in name resolution')); 3138)
[2023-07-31T12:46:54.491+0000] {local_task_job.py:159} INFO - Task exited with return code 1
[2023-07-31T12:46:55.187+0000] {taskinstance.py:2582} INFO - 0 downstream tasks scheduled from follow-on schedule check
