[2023-07-27T09:36:13.409+0000] {taskinstance.py:1087} INFO - Dependencies all met for <TaskInstance: data_engineer_jobs_dag.get_data_from_api scheduled__2023-03-26T00:00:00+00:00 [queued]>
[2023-07-27T09:36:13.629+0000] {taskinstance.py:1087} INFO - Dependencies all met for <TaskInstance: data_engineer_jobs_dag.get_data_from_api scheduled__2023-03-26T00:00:00+00:00 [queued]>
[2023-07-27T09:36:13.631+0000] {taskinstance.py:1283} INFO - 
--------------------------------------------------------------------------------
[2023-07-27T09:36:13.778+0000] {taskinstance.py:1284} INFO - Starting attempt 1 of 2
[2023-07-27T09:36:13.779+0000] {taskinstance.py:1285} INFO - 
--------------------------------------------------------------------------------
[2023-07-27T09:36:14.709+0000] {taskinstance.py:1304} INFO - Executing <Task(PythonOperator): get_data_from_api> on 2023-03-26 00:00:00+00:00
[2023-07-27T09:36:14.752+0000] {standard_task_runner.py:55} INFO - Started process 10166 to run task
[2023-07-27T09:36:14.817+0000] {standard_task_runner.py:82} INFO - Running: ['***', 'tasks', 'run', 'data_engineer_jobs_dag', 'get_data_from_api', 'scheduled__2023-03-26T00:00:00+00:00', '--job-id', '1383', '--raw', '--subdir', 'DAGS_FOLDER/load_data.py', '--cfg-path', '/tmp/tmpjdr2bhfv']
[2023-07-27T09:36:14.845+0000] {standard_task_runner.py:83} INFO - Job 1383: Subtask get_data_from_api
[2023-07-27T09:36:16.111+0000] {task_command.py:389} INFO - Running <TaskInstance: data_engineer_jobs_dag.get_data_from_api scheduled__2023-03-26T00:00:00+00:00 [running]> on host bc3380e7707e
[2023-07-27T09:36:19.162+0000] {taskinstance.py:1513} INFO - Exporting the following env vars:
AIRFLOW_CTX_DAG_EMAIL=kasimir.Ikuenobe@hotmail.com
AIRFLOW_CTX_DAG_OWNER=ebejale
AIRFLOW_CTX_DAG_ID=data_engineer_jobs_dag
AIRFLOW_CTX_TASK_ID=get_data_from_api
AIRFLOW_CTX_EXECUTION_DATE=2023-03-26T00:00:00+00:00
AIRFLOW_CTX_TRY_NUMBER=1
AIRFLOW_CTX_DAG_RUN_ID=scheduled__2023-03-26T00:00:00+00:00
[2023-07-27T09:36:44.884+0000] {taskinstance.py:1772} ERROR - Task failed with exception
Traceback (most recent call last):
  File "/home/airflow/.local/lib/python3.7/site-packages/urllib3/connectionpool.py", line 710, in urlopen
    chunked=chunked,
  File "/home/airflow/.local/lib/python3.7/site-packages/urllib3/connectionpool.py", line 386, in _make_request
    self._validate_conn(conn)
  File "/home/airflow/.local/lib/python3.7/site-packages/urllib3/connectionpool.py", line 1042, in _validate_conn
    conn.connect()
  File "/home/airflow/.local/lib/python3.7/site-packages/urllib3/connection.py", line 424, in connect
    tls_in_tls=tls_in_tls,
  File "/home/airflow/.local/lib/python3.7/site-packages/urllib3/util/ssl_.py", line 450, in ssl_wrap_socket
    sock, context, tls_in_tls, server_hostname=server_hostname
  File "/home/airflow/.local/lib/python3.7/site-packages/urllib3/util/ssl_.py", line 493, in _ssl_wrap_socket_impl
    return ssl_context.wrap_socket(sock, server_hostname=server_hostname)
  File "/usr/local/lib/python3.7/ssl.py", line 423, in wrap_socket
    session=session
  File "/usr/local/lib/python3.7/ssl.py", line 870, in _create
    self.do_handshake()
  File "/usr/local/lib/python3.7/ssl.py", line 1139, in do_handshake
    self._sslobj.do_handshake()
OSError: [Errno 0] Error

During handling of the above exception, another exception occurred:

Traceback (most recent call last):
  File "/home/airflow/.local/lib/python3.7/site-packages/requests/adapters.py", line 499, in send
    timeout=timeout,
  File "/home/airflow/.local/lib/python3.7/site-packages/urllib3/connectionpool.py", line 788, in urlopen
    method, url, error=e, _pool=self, _stacktrace=sys.exc_info()[2]
  File "/home/airflow/.local/lib/python3.7/site-packages/urllib3/util/retry.py", line 550, in increment
    raise six.reraise(type(error), error, _stacktrace)
  File "/home/airflow/.local/lib/python3.7/site-packages/urllib3/packages/six.py", line 769, in reraise
    raise value.with_traceback(tb)
  File "/home/airflow/.local/lib/python3.7/site-packages/urllib3/connectionpool.py", line 710, in urlopen
    chunked=chunked,
  File "/home/airflow/.local/lib/python3.7/site-packages/urllib3/connectionpool.py", line 386, in _make_request
    self._validate_conn(conn)
  File "/home/airflow/.local/lib/python3.7/site-packages/urllib3/connectionpool.py", line 1042, in _validate_conn
    conn.connect()
  File "/home/airflow/.local/lib/python3.7/site-packages/urllib3/connection.py", line 424, in connect
    tls_in_tls=tls_in_tls,
  File "/home/airflow/.local/lib/python3.7/site-packages/urllib3/util/ssl_.py", line 450, in ssl_wrap_socket
    sock, context, tls_in_tls, server_hostname=server_hostname
  File "/home/airflow/.local/lib/python3.7/site-packages/urllib3/util/ssl_.py", line 493, in _ssl_wrap_socket_impl
    return ssl_context.wrap_socket(sock, server_hostname=server_hostname)
  File "/usr/local/lib/python3.7/ssl.py", line 423, in wrap_socket
    session=session
  File "/usr/local/lib/python3.7/ssl.py", line 870, in _create
    self.do_handshake()
  File "/usr/local/lib/python3.7/ssl.py", line 1139, in do_handshake
    self._sslobj.do_handshake()
urllib3.exceptions.ProtocolError: ('Connection aborted.', OSError(0, 'Error'))

During handling of the above exception, another exception occurred:

Traceback (most recent call last):
  File "/home/airflow/.local/lib/python3.7/site-packages/airflow/operators/python.py", line 175, in execute
    return_value = self.execute_callable()
  File "/home/airflow/.local/lib/python3.7/site-packages/airflow/operators/python.py", line 192, in execute_callable
    return self.python_callable(*self.op_args, **self.op_kwargs)
  File "/opt/airflow/dags/load_data.py", line 62, in get_data_from_api
    response = requests.get(url, headers=headers, params=querystring)
  File "/home/airflow/.local/lib/python3.7/site-packages/requests/api.py", line 73, in get
    return request("get", url, params=params, **kwargs)
  File "/home/airflow/.local/lib/python3.7/site-packages/requests/api.py", line 59, in request
    return session.request(method=method, url=url, **kwargs)
  File "/home/airflow/.local/lib/python3.7/site-packages/requests/sessions.py", line 587, in request
    resp = self.send(prep, **send_kwargs)
  File "/home/airflow/.local/lib/python3.7/site-packages/requests/sessions.py", line 701, in send
    r = adapter.send(request, **kwargs)
  File "/home/airflow/.local/lib/python3.7/site-packages/requests/adapters.py", line 547, in send
    raise ConnectionError(err, request=request)
requests.exceptions.ConnectionError: ('Connection aborted.', OSError(0, 'Error'))
[2023-07-27T09:36:45.439+0000] {taskinstance.py:1327} INFO - Marking task as UP_FOR_RETRY. dag_id=data_engineer_jobs_dag, task_id=get_data_from_api, execution_date=20230326T000000, start_date=20230727T093613, end_date=20230727T093645
[2023-07-27T09:36:46.529+0000] {standard_task_runner.py:105} ERROR - Failed to execute job 1383 for task get_data_from_api (('Connection aborted.', OSError(0, 'Error')); 10166)
[2023-07-27T09:36:46.549+0000] {local_task_job.py:159} INFO - Task exited with return code 1
[2023-07-27T09:36:46.628+0000] {taskinstance.py:2582} INFO - 0 downstream tasks scheduled from follow-on schedule check
